<?xml version="1.0"?>
<robot name="caster"  xmlns:xacro="http://www.ros.org/wiki/xacro">

	<!-- Caster -->
	<property name="caster_radius" value="0.1" /> 
	<property name="caster_mass" value="0.5" /> <!-- in kg-->
  
	<xacro:macro name="caster" params="lr parent translateX translateY translateZ"> <!-- lr: left, right -->
		<link name="${lr}_caster">
		<visual>
			<origin xyz="0 0 0" rpy="0 0  0 " /> 
			<geometry>
				<sphere radius="${caster_radius}" />
			</geometry>
			<material name="grey"><color rgba="0.4 0.4 0.4 1"/></material>
		</visual>
		<collision>
			<origin xyz="0 0 0" rpy="0 0 0" />
			<geometry><sphere radius="${caster_radius}" /></geometry>
		</collision>
		<inertial>
			<mass value="${caster_mass}"/>
			<inertia ixx="0.0001" ixy="0.0" ixz="0.0" iyy="0.0001" iyz="0.0" izz="0.0001"/>
		</inertial>
	</link>

	<gazebo reference="${lr}_caster">
		<material>Gazebo/Grey</material>
		<!-- <turnGravityOff>false</turnGravityOff> -->
	</gazebo>

	<joint name="${lr}_caster_joint" type="continuous">
		<parent link="${parent}"/>
		<child link="${lr}_caster"/>
		<origin xyz="${translateX} ${translateY} ${translateZ}" rpy="0 0 0" /> 
		<axis xyz="0 1 0" />
	</joint>
	
	<!-- Transmission is important to link the joints and the controller -->
	<transmission name="${lr}_caster_joint_trans">
		<type>transmission_interface/SimpleTransmission</type>
		<joint name="${lr}_caster_joint"/>
		<actuator name="${lr}_caster_joint_motor">
			<hardwareInterface>EffortJointInterface</hardwareInterface>
			<mechanicalReduction>1</mechanicalReduction>
		</actuator>
    </transmission>

    </xacro:macro>
</robot>
