<?xml version="1.0"?>
<robot name="wheel"  xmlns:xacro="http://www.ros.org/wiki/xacro">

	<!-- Wheels -->
	<property name="wheel_radius" value="0.2" /> 
	<property name="wheel_height" value="0.1" />
	<property name="wheel_mass" value="1" /> <!-- in kg-->
  
	<macro name="cylinder_inertia" params="m r h">
		<inertia  ixx="${m*(3*r*r+h*h)/12}" ixy = "0" ixz = "0" iyy="${m*(3*r*r+h*h)/12}" iyz = "0" izz="${m*r*r/2}" /> 
	</macro>
  
	<xacro:macro name="wheel" params="lr parent translateX translateY translateZ flipY"> <!-- lr: left, right -->
		<link name="${lr}_wheel">
		<visual>
			<origin xyz="0 0 0" rpy="${flipY*M_PI/2} 0  0 " /> 
			<geometry>
				<cylinder length="${wheel_height}" radius="${wheel_radius}" />
			</geometry>
			<material name="grey"><color rgba="0.4 0.4 0.4 1"/></material>
		</visual>
		<collision>
			<origin xyz="0 0 0" rpy="${flipY*M_PI/2} 0 0" />
			<geometry><cylinder length="${wheel_height}" radius="${wheel_radius}" /></geometry>
		</collision>
		<inertial>
			<mass value="${wheel_mass}" />
			<origin xyz="0 0 0" />
			<cylinder_inertia  m="${wheel_mass}" r="${wheel_radius}" h="${wheel_height}" />
		</inertial>
	</link>

	<gazebo reference="${lr}_wheel">
		<material>Gazebo/Grey</material>
		<!-- <turnGravityOff>false</turnGravityOff> -->
	</gazebo>
	<!-- Il giunto puo essere solo fisso o continuo con il tag della trasmissione -->
	<joint name="${lr}_wheel_joint" type="continuous">
		<parent link="${parent}"/>
		<child link="${lr}_wheel"/>
		<origin xyz="${translateX} ${translateY} ${translateZ}" rpy="0 0 0" /> 
		<axis xyz="0 1 0" />
		<limit effort="100.0" lower="0.0" upper="0.0" velocity="100"/>
		<joint_properties damping="0.0" friction="0.0"/>
	</joint>

	<!-- Transmission is important to link the joints and the controller -->
	<transmission name="${lr}_wheel_joint_trans">
		<type>transmission_interface/SimpleTransmission</type>
		<joint name="${lr}_wheel_joint"/>
		<actuator name="${lr}_wheel_joint_motor">
			<hardwareInterface>EffortJointInterface</hardwareInterface>
			<mechanicalReduction>1</mechanicalReduction>
		</actuator>
    </transmission>
    
    </xacro:macro>
</robot>
