<?xml version="1.0"?>

<robot xmlns:xacro="http://www.ros.org/wiki/xacro">
	
	<!-- Inertia matrix -->
	<xacro:macro name="cylinder_inertia" params="m r h">
		<inertia  ixx="${m*(3*r*r+h*h)/12}" ixy = "0" ixz = "0" iyy="${m*(3*r*r+h*h)/12}" iyz = "0" izz="${m*r*r/2}" /> 
	</xacro:macro>
	<xacro:macro name="box_inertia" params="m w l h">
		<inertia  ixx="${m*(w*w+h*h)/12}" ixy = "0" ixz = "0" iyy="${m*(l*l+h*h)/12}" iyz = "0" izz="${m*(l*l+h*h)/12}" /> 
	</xacro:macro>


	<!-- Wheels-->
	<xacro:macro name="wheel" params="side translateX translateY translateZ"> 
		<link name="${side}_wheel">
			<visual>
				<origin xyz="0 0 0" rpy="${PI/2} 0 0"/>
				<geometry>
					<cylinder length="${wheel_height}" radius="${wheel_radius}" />
				</geometry>
				<material name="grey"><color rgba="0.4 0.4 0.4 1"/></material>
			</visual>
			<collision>
				<origin xyz="0 0 0" rpy="${PI/2} 0 0"/>
				<geometry><cylinder length="${wheel_height}" radius="${wheel_radius}" /></geometry>
			</collision>
			<inertial>
				<mass value="${wheel_mass}" />
				<origin xyz="0 0 0" rpy="${PI/2} 0 0"/>
				<xacro:cylinder_inertia  m="${wheel_mass}" r="${wheel_radius}" h="${wheel_height}"/>
			</inertial>
		</link>

		<joint name="${side}_wheel_joint" type="continuous">
			<parent link="base_link"/>
			<child link="${side}_wheel"/>
			<origin xyz="${translateX} ${translateY} ${translateZ}" rpy="0 0 0" /> 
			<axis xyz="0 1 0" />
			<limit effort="100.0" lower="0.0" upper="0.0" velocity="100"/>
			<dynamics damping="0.0" friction="0.0"/>
		</joint>
    </xacro:macro>
	
	<xacro:wheel side="right" translateX="-0.15" translateY="-0.3" translateZ="-0.125" />
	<xacro:wheel side="left" translateX="-0.15" translateY="0.3" translateZ="-0.125" />
	
	
	<!-- Caster -->
	<xacro:macro name="caster" params="side X_mount Y_mount Z_mount X_dummy Y_dummy Z_dummy X_wheel Y_wheel Z_wheel">
		
		<!-- caster mount link -->
		<link name="${side}_castor_mount_link">
			<collision>
				<geometry>
					<box size="${castor_mount_link_length} ${castor_mount_link_width} ${castor_mount_link_height}"/>
				</geometry>
				<origin xyz="0 0 0" rpy="0 0 0" />
			</collision>
			<visual>
				<geometry>
					<box size="${castor_mount_link_length} ${castor_mount_link_width} ${castor_mount_link_height}"/>
				</geometry>
				<origin xyz="0 0 0" rpy="0 0 0" />
				<material name="white"><color rgba="1 1 1 1"/></material>
			</visual>
			<inertial>
				<origin xyz="0 0 0" rpy="0 0 0" />
				<mass value="${castor_mount_link_mass}"/>
				<xacro:box_inertia  m="${castor_mount_link_mass}" 
									w="${castor_mount_link_width}" 
									l="${castor_mount_link_length}" 
									h="${castor_mount_link_height}" />
			</inertial>      
		</link>
		
		<joint name="${side}_castor_mount_joint" type="fixed">
			<parent link="base_link"/>
			<child link="${side}_castor_mount_link"/>
			<origin xyz="${X_mount} ${Y_mount} ${Z_mount}" />
		</joint>
		
		<!-- caster dummy link -->
		<link name="${side}_castor_dummy_link">
			<collision>
				<geometry>
					<box size="${castor_dummy_link_length} ${castor_dummy_link_width} ${castor_dummy_link_height}"/>
				</geometry>
				<origin xyz="0 0 0" rpy="0 0 0" />
			</collision>
			<visual>
				<geometry>
					<box size="${castor_dummy_link_length} ${castor_dummy_link_width} ${castor_dummy_link_height}"/>
				</geometry>
				<origin xyz="0 0 0" rpy="0 0 0" />
				<material name="white"><color rgba="1 1 1 1"/></material>
			</visual>
			<inertial>
				<origin xyz="0 0 0" rpy="0 0 0" />
				<mass value="${castor_mount_link_mass}"/>
				<xacro:box_inertia  m="${castor_dummy_link_mass}" 
									w="${castor_dummy_link_width}" 
									l="${castor_dummy_link_length}" 
									h="${castor_dummy_link_height}" />
			</inertial>      
		</link>
		
		<joint name="${side}_castor_dummy_joint" type="continuous">
			<axis xyz="0 0 1"/>
			<parent link="${side}_castor_mount_link"/>
			<child link="${side}_castor_dummy_link"/>
			<origin xyz="${X_dummy} ${Y_dummy} ${Z_dummy}" />
			<dynamics friction="${joint_friction}"/> 
		</joint>
		
		<!-- caster wheel -->
		<link name="${side}_castor_wheel_link">
			<collision>
				<geometry>
					<cylinder length="${castor_wheel_length}" radius="${castor_wheel_radius}"/>
				</geometry>
				<origin xyz="0 0 0" rpy="${PI/2} 0 0"/>
			</collision>
			<visual>
				<geometry>
					<cylinder length="${castor_wheel_length}" radius="${castor_wheel_radius}"/>
				</geometry>
				<origin xyz="0 0 0" rpy="${PI/2} 0 0"/>
				<material name="grey"><color rgba="0.4 0.4 0.4 1"/></material>
			</visual>
			<inertial>
				<origin xyz="0 0 0" rpy="${PI/2} 0 0"/>
				<mass value="${castor_wheel_mass}"/>
				<xacro:cylinder_inertia m="${castor_wheel_mass}" 
										r="${castor_wheel_radius}" 
										h="${castor_wheel_length}" />
			</inertial>
		</link>
		
		<joint name="${side}_castor_wheel_joint" type="continuous">
			<axis xyz="0 1 0"/>
			<parent link="${side}_castor_dummy_link"/>
			<child link="${side}_castor_wheel_link"/>
			<origin xyz="${X_wheel} ${Y_wheel} ${Z_wheel}" />
			<dynamics friction="${joint_friction}"/> 
		</joint>
    </xacro:macro>
	
	<xacro:caster side="left" 
				  X_mount="0.375" Y_mount="0.275" Z_mount="-0.09" 
				  X_dummy="0.0" Y_dummy="0.0" Z_dummy="-0.015" 
				  X_wheel="-0.05" Y_wheel="0.0" Z_wheel="-0.12" />
	<xacro:caster side="right" 
				  X_mount="0.375" Y_mount="-0.275" Z_mount="-0.09" 
	  		      X_dummy="0.0" Y_dummy="0.0" Z_dummy="-0.015" 
				  X_wheel="-0.05" Y_wheel="0.0" Z_wheel="-0.12" />
</robot>